Workbook

Sheet Sheet2
A1: Data returned for Sum of Revenue, Groceries (First 1000 rows).
A3: tblOrders[OrderID] | B3: tblOrders[OrderDate] | C3: tblOrders[CustomerName] | D3: tblOrders[Region] | E3: tblOrders[City] | F3: tblOrders[Category] | G3: tblOrders[Product] | H3: tblOrders[Channel] | I3: tblOrders[Quantity] | J3: tblOrders[UnitPrice] | K3: tblOrders[Discount] | L3: tblOrders[PaymentMethod] | M3: tblOrders[OrderStatus] | N3: tblOrders[SalesRep] | O3: tblOrders[Notes] | P3: tblOrders[CustomerName_Clean] | Q3: tblOrders[Region_Clean] | R3: tblOrders[Category_Clean] | S3: tblOrders[Channel_Clean] | T3: tblOrders[PaymentMethod_Clean] | U3: tblOrders[OrderStatus_Cleaned] | V3: tblOrders[Quantity_Clean] | W3: tblOrders[UnitPrice_Clean] | X3: tblOrders[OrderDate_Clean] | Y3: tblOrders[Discount_Clean] | Z3: tblOrders[Notes_Clean] | AA3: tblOrders[HighValueFlag] | AB3: tblOrders[Revenue] | AC3: tblOrders[OrderID_Key] | AD3: tblOrders[OrderNumber] | AE3: tblOrders[MonthLabel] | AF3: tblOrders[MonthEndDate] | AG3: tblOrders[FirstName] | AH3: tblOrders[Column1]
A4: ORD-1217 | B4: 2024-12-22 | C4: GRACE FAROOQ | D4: EAST | E4: Sialkot | F4: groceries | G4: Basmati Rice 5kg | H4: Online | I4: 8 | J4: $474.88 | K4: 0.1 | L4: Bank Transfer | M4: PENDING | N4: E. Tanaka | O4: Follow up needed | P4: Grace Farooq | Q4: East | R4: Groceries | S4: Online | T4: Bank Transfer | U4: Pending | V4: 8 | W4: 474.88 | X4: 45648 | Y4: 0.1 | Z4: Follow up needed | AA4: High Value | AB4: 3799.04 | AC4: ORD-1217 | AD4: 1217 | AE4: Dec-2024 | AF4: 45657 | AG4: Grace
A5: ORD-1143 | B5: 24/03/2024 | C5: Bilal Hussain | D5: South | E5: Karachi | F5: groceries | G5: Almonds 500g | H5: Online | I5: 5 | J5: $330.74 | L5: Credit card | M5: Refunded | N5: A. Malik | P5: Bilal Hussain | Q5: South | R5: Groceries | S5: Online | T5: Credit Card | U5: Refunded | V5: 5 | W5: 330.74 | X5: 45375 | Y5: 0 | AA5: High Value | AB5: 1653.7 | AC5: ORD-1143 | AD5: 1143 | AE5: Mar-2024 | AF5: 45382 | AG5: bilal
A6: ORD-1099 | B6: 25/09/2024 | C6: Grace Khan | D6: west | E6: Quetta | F6: groceries | G6: Olive Oil 1L | H6: In-store | J6: $286.14 | K6: 0.1 | L6: debit card | M6: PENDING | N6: E. Tanaka | O6: Follow up needed | P6: Grace Khan | Q6: West | R6: Groceries | S6: In-Store | T6: Debit Card | U6: Pending | W6: 286.14 | X6: 45560 | Y6: 0.1 | Z6: Follow up needed | AA6: Review | AB6: 0 | AC6: ORD-1099 | AD6: 1099 | AE6: Sep-2024 | AF6: 45565 | AG6: Grace
A7: ORD-1060 | B7: 28-Feb-24 | C7: Grace Taylor | D7: Nort | E7: Lahore | F7: groceries | G7: Green Tea Pack | H7: In-store | I7: 6 | J7: $256.17 | K7: 0 | L7: debit card | M7: PENDING | N7: C. Osei | O7: VIP customer | P7: Grace Taylor | Q7: North | R7: Groceries | S7: In-Store | T7: Debit Card | U7: Pending | V7: 6 | W7: 256.17 | X7: 45350 | Y7: 0 | Z7: VIP customer | AA7: High Value | AB7: 1537.02 | AC7: ORD-1060 | AD7: 1060 | AE7: Feb-2024 | AF7: 45351 | AG7: Grace
A8: ORD-1153 | B8: 12/09/2024 | C8: Sarah Malik | D8: west | F8: groceries | G8: Green Tea Pack | H8: Online | I8: 3 | J8: $225.78 | K8: 20% | L8: Credit card | M8: PENDING | N8: C. Osei | O8: Bulk order - business account | P8: Sarah Malik | Q8: West | R8: Groceries | S8: Online | T8: Credit Card | U8: Pending | V8: 3 | W8: 225.78 | X8: 45635 | Y8: 20% | Z8: Bulk order - business account | AA8: Standard | AB8: 677.34 | AC8: ORD-1153 | AD8: 1153 | AE8: Dec-2024 | AF8: 45657 | AG8: sarah
A9: ORD-1027 | B9: July 20, 2024 | C9: MARIA ANDERSON | D9: South | E9: Karachi | F9: groceries | G9: Almonds 500g | H9: In-store | I9: 11 | J9: $205.14 | K9: 0.05 | L9: cash | M9: PENDING | N9: A. Malik | O9: Gift wrap requested | P9: Maria Anderson | Q9: South | R9: Groceries | S9: In-Store | T9: Cash | U9: Pending | V9: 11 | W9: 205.14 | X9: 45493 | Y9: 0.05 | Z9: Gift wrap requested | AA9: High Value | AB9: 2256.54 | AC9: ORD-1027 | AD9: 1027 | AE9: Jul-2024 | AF9: 45504 | AG9: maria
A10: ORD-1027 | B10: July 20, 2024 | C10: MARIA ANDERSON | D10: South | E10: Karachi | F10: groceries | G10: Almonds 500g | H10: In-store | I10: 11 | J10: $205.14 | K10: 0.05 | L10: cash | M10: PENDING | N10: A. Malik | O10: Gift wrap requested | P10: Maria Anderson | Q10: South | R10: Groceries | S10: In-Store | T10: Cash | U10: Pending | V10: 11 | W10: 205.14 | X10: 45493 | Y10: 0.05 | Z10: Gift wrap requested | AA10: High Value | AB10: 2256.54 | AC10: ORD-1027 | AD10: 1027 | AE10: Jul-2024 | AF10: 45504 | AG10: maria
A11: ORD-1033 | B11: August 30, 2024 | C11: Grace Smith | D11: South | E11: Karachi | F11: groceries | G11: Almonds 500g | H11: instore | I11: 8 | J11: 51.06 | K11: 10% | L11: cash | M11: PENDING | N11: C. Osei | O11: Bulk order - business account | P11: Grace Smith | Q11: South | R11: Groceries | S11: In-Store | T11: Cash | U11: Pending | V11: 8 | W11: 51.06 | X11: 45534 | Y11: 10% | Z11: Bulk order - business account | AA11: Standard | AB11: 408.48 | AC11: ORD-1033 | AD11: 1033 | AE11: Aug-2024 | AF11: 45535 | AG11: Grace
A12: ORD-1032 | B12: May 23, 2024 | C12: olivia lewis | D12: EAST | E12: Multan | F12: groceries | G12: Almonds 500g | H12: In Store | J12: 426.22 | L12: Bank Transfer | M12: cancelled | N12: C. Osei | O12: Leave at front desk | P12: Olivia Lewis | Q12: East | R12: Groceries | S12: In-Store | T12: Bank Transfer | U12: Cancelled | W12: 426.22 | X12: 45435 | Y12: 0 | Z12: Leave at front desk | AA12: Review | AB12: 0 | AC12: ORD-1032 | AD12: 1032 | AE12: May-2024 | AF12: 45443 | AG12: OLIVIA
A13: ORD-1136 | B13: 2024-05-20 | C13: Nida Taylor | D13: north | E13: Islamabad | F13: groceries | G13: Basmati Rice 5kg | H13: Online | I13: 8 | J13: 495.96 | K13: 0.05 | L13: cash | M13: cancelled | N13: B. Fernandes | P13: Nida Taylor | Q13: North | R13: Groceries | S13: Online | T13: Cash | U13: Cancelled | V13: 8 | W13: 495.96 | X13: 45432 | Y13: 0.05 | AA13: High Value | AB13: 3967.68 | AC13: ORD-1136 | AD13: 1136 | AE13: May-2024 | AF13: 45443 | AG13: Nida
A14: ORD-1175 | B14: 03-Aug-24 | C14: Yusuf Sheikh | D14: EAST | E14: Multan | F14: groceries | G14: Green Tea Pack | H14: In-store | I14: 3 | J14: 450.3 | L14: Credit card | M14: Refunded | N14: C. Osei | P14: Yusuf Sheikh | Q14: East | R14: Groceries | S14: In-Store | T14: Credit Card | U14: Refunded | V14: 3 | W14: 450.3 | X14: 45507 | Y14: 0 | AA14: High Value | AB14: 1350.9 | AC14: ORD-1175 | AD14: 1175 | AE14: Aug-2024 | AF14: 45535 | AG14: Yusuf
A15: ORD-1164 | B15: 13-Feb-24 | C15: MICHAEL FAROOQ | D15: South | E15: Hyderabad | F15: groceries | G15: Green Tea Pack | H15: instore | I15: 8 | J15: 419.35 | L15: Bank Transfer | M15: PENDING | N15: A. Malik | O15: Bulk order - business account | P15: Michael Farooq | Q15: South | R15: Groceries | S15: In-Store | T15: Bank Transfer | U15: Pending | V15: 8 | W15: 419.35 | X15: 45335 | Y15: 0 | Z15: Bulk order - business account | AA15: High Value | AB15: 3354.8 | AC15: ORD-1164 | AD15: 1164 | AE15: Feb-2024 | AF15: 45351 | AG15: Michael
A16: ORD-1031 | B16: 02/10/2024 | C16: Grace Hussain | D16: EAST | F16: groceries | G16: Basmati Rice 5kg | H16: In Store | I16: 6 | J16: 415.21 | K16: 0.2 | L16: cash | M16: cancelled | N16: E. Tanaka | O16: Damaged on arrival - replaced | P16: Grace Hussain | Q16: East | R16: Groceries | S16: In-Store | T16: Cash | U16: Cancelled | V16: 6 | W16: 415.21 | X16: 45332 | Y16: 0.2 | Z16: Damaged on arrival - replaced | AA16: High Value | AB16: 2491.26 | AC16: ORD-1031 | AD16: 1031 | AE16: Feb-2024 | AF16: 45351 | AG16: Grace
A17: ORD-1092 | B17: 09-Nov-24 | C17: chen sheikh | D17: EAST | E17: Multan | F17: groceries | G17: Basmati Rice 5kg | H17: Online | I17: 3 | J17: 402.96 | L17: cash | M17: COMPLETED | N17: C. Osei | O17: Follow up needed | P17: Chen Sheikh | Q17: East | R17: Groceries | S17: Online | T17: Cash | U17: Completed | V17: 3 | W17: 402.96 | X17: 45605 | Y17: 0 | Z17: Follow up needed | AA17: High Value | AB17: 1208.88 | AC17: ORD-1092 | AD17: 1092 | AE17: Nov-2024 | AF17: 45626 | AG17: Chen
A18: ORD-1073 | B18: 11-Mar-24 | C18: daniel qureshi | D18: west | E18: Quetta | F18: groceries | G18: Green Tea Pack | H18: instore | I18: 8 | J18: 390.17 | K18: 0.05 | L18: Credit card | M18: Refunded | N18: E. Tanaka | O18: Gift wrap requested | P18: Daniel Qureshi | Q18: West | R18: Groceries | S18: In-Store | T18: Credit Card | U18: Refunded | V18: 8 | W18: 390.17 | X18: 45362 | Y18: 0.05 | Z18: Gift wrap requested | AA18: High Value | AB18: 3121.36 | AC18: ORD-1073 | AD18: 1073 | AE18: Mar-2024 | AF18: 45382 | AG18: daniel
A19: ORD-1104 | B19: 04-Aug-24 | C19: MICHAEL CLARK | D19: Nort | E19: Islamabad | F19: groceries | G19: Honey Jar | H19: instore | I19: 11 | J19: 363.02 | K19: 0.05 | L19: cash | M19: COMPLETED | N19: A. Malik | O19: Customer called twice | P19: Michael Clark | Q19: North | R19: Groceries | S19: In-Store | T19: Cash | U19: Completed | V19: 11 | W19: 363.02 | X19: 45508 | Y19: 0.05 | Z19: Customer called twice | AA19: High Value | AB19: 3993.22 | AC19: ORD-1104 | AD19: 1104 | AE19: Aug-2024 | AF19: 45535 | AG19: Michael
A20: ORD-1052 | B20: 2024-08-29 | C20: Daniel Johnson | D20: South | E20: Hyderabad | F20: groceries | G20: Green Tea Pack | H20: In-store | I20: 2 | J20: 338.05 | K20: 10% | L20: Credit card | M20: PENDING | N20: B. Fernandes | O20: Bulk order - business account | P20: Daniel Johnson | Q20: South | R20: Groceries | S20: In-Store | T20: Credit Card | U20: Pending | V20: 2 | W20: 338.05 | X20: 45533 | Y20: 10% | Z20: Bulk order - business account | AA20: Standard | AB20: 676.1 | AC20: ORD-1052 | AD20: 1052 | AE20: Aug-2024 | AF20: 45535 | AG20: daniel
A21: ORD-1011 | B21: 26/03/2024 | C21: Ahmed Garcia | D21: west | E21: Peshawar | F21: groceries | G21: Basmati Rice 5kg | H21: instore | I21: 9 | J21: 327.81 | L21: Credit card | M21: Refunded | N21: B. Fernandes | O21: Damaged on arrival - replaced | P21: Ahmed Garcia | Q21: West | R21: Groceries | S21: In-Store | T21: Credit Card | U21: Refunded | V21: 9 | W21: 327.81 | X21: 45377 | Y21: 0 | Z21: Damaged on arrival - replaced | AA21: High Value | AB21: 2950.29 | AC21: ORD-1011 | AD21: 1011 | AE21: Mar-2024 | AF21: 45382 | AG21: Ahmed
A22: ORD-1085 | B22: November 23, 2024 | C22: Daniel Farooq | D22: north | E22: Lahore | F22: groceries | G22: Almonds 500g | H22: Online | I22: 3 | J22: 322.96 | K22: 10% | L22: Credit card | M22: Refunded | N22: E. Tanaka | O22: Follow up needed | P22: Daniel Farooq | Q22: North | R22: Groceries | S22: Online | T22: Credit Card | U22: Refunded | V22: 3 | W22: 322.96 | X22: 45619 | Y22: 10% | Z22: Follow up needed | AA22: Standard | AB22: 968.88 | AC22: ORD-1085 | AD22: 1085 | AE22: Nov-2024 | AF22: 45626 | AG22: daniel
A23: ORD-1166 | B23: July 22, 2024 | C23: Emily Lee | D23: South | E23: Karachi | F23: groceries | G23: Almonds 500g | H23: Online | I23: 11 | J23: 299.55 | K23: 0 | L23: Credit card | M23: Canceled | N23: E. Tanaka | P23: Emily Lee | Q23: South | R23: Groceries | S23: Online | T23: Credit Card | U23: Cancelled | V23: 11 | W23: 299.55 | X23: 45495 | Y23: 0 | AA23: High Value | AB23: 3295.05 | AC23: ORD-1166 | AD23: 1166 | AE23: Jul-2024 | AF23: 45504 | AG23: EMILY
A24: ORD-1077 | B24: 23/01/2024 | C24: BILAL BROWN | D24: west | E24: Peshawar | F24: groceries | G24: Basmati Rice 5kg | H24: In-store | I24: 6 | J24: 265.4 | K24: 0.2 | L24: Credit card | M24: Canceled | N24: D. Iqbal | P24: Bilal Brown | Q24: West | R24: Groceries | S24: In-Store | T24: Credit Card | U24: Cancelled | V24: 6 | W24: 265.4 | X24: 45314 | Y24: 0.2 | AA24: High Value | AB24: 1592.4 | AC24: ORD-1077 | AD24: 1077 | AE24: Jan-2024 | AF24: 45322 | AG24: bilal
A25: ORD-1151 | B25: 2024-03-12 | C25: Ahmed Taylor | D25: north | E25: Islamabad | F25: groceries | G25: Green Tea Pack | H25: In-store | J25: 205.17 | K25: 0.05 | L25: Credit card | M25: cancelled | N25: A. Malik | O25: Gift wrap requested | P25: Ahmed Taylor | Q25: North | R25: Groceries | S25: In-Store | T25: Credit Card | U25: Cancelled | W25: 205.17 | X25: 45363 | Y25: 0.05 | Z25: Gift wrap requested | AA25: Review | AB25: 0 | AC25: ORD-1151 | AD25: 1151 | AE25: Mar-2024 | AF25: 45382 | AG25: Ahmed
A26: ORD-1132 | B26: April 17, 2024 | C26: UMAR FAROOQ | D26: north | E26: Lahore | F26: groceries | G26: Olive Oil 1L | H26: In-store | I26: 1 | J26: 177.55 | K26: 0 | L26: Bank Transfer | M26: Refunded | N26: B. Fernandes | P26: Umar Farooq | Q26: North | R26: Groceries | S26: In-Store | T26: Bank Transfer | U26: Refunded | V26: 1 | W26: 177.55 | X26: 45399 | Y26: 0 | AA26: Standard | AB26: 177.55 | AC26: ORD-1132 | AD26: 1132 | AE26: Apr-2024 | AF26: 45412 | AG26: UMAR
A27: ORD-1106 | B27: August 02, 2024 | C27: Chen Clark | D27: South | E27: Karachi | F27: groceries | G27: Honey Jar | H27: In Store | I27: 4 | J27: 176.35 | K27: 0 | L27: Credit card | M27: Refunded | O27: Gift wrap requested | P27: Chen Clark | Q27: South | R27: Groceries | S27: In-Store | T27: Credit Card | U27: Refunded | V27: 4 | W27: 176.35 | X27: 45506 | Y27: 0 | Z27: Gift wrap requested | AA27: Standard | AB27: 705.4 | AC27: ORD-1106 | AD27: 1106 | AE27: Aug-2024 | AF27: 45535 | AG27: Chen
A28: ORD-1210 | B28: 03/25/2024 | C28: NOAH MALIK | D28: west | E28: Quetta | F28: groceries | G28: Honey Jar | H28: In Store | I28: 6 | J28: 175.79 | K28: 0 | L28: cash | M28: COMPLETED | N28: D. Iqbal | O28: Customer called twice | P28: Noah Malik | Q28: West | R28: Groceries | S28: In-Store | T28: Cash | U28: Completed | V28: 6 | W28: 175.79 | X28: 45376 | Y28: 0 | Z28: Customer called twice | AA28: High Value | AB28: 1054.74 | AC28: ORD-1210 | AD28: 1210 | AE28: Mar-2024 | AF28: 45382 | AG28: Noah
A29: ORD-1122 | B29: 20/11/2024 | C29: MARIA SMITH | D29: East | E29: Sialkot | F29: groceries | G29: Green Tea Pack | H29: In-store | I29: 10 | J29: 104.42 | K29: 0.1 | L29: CC | M29: Refunded | O29: VIP customer | P29: Maria Smith | Q29: East | R29: Groceries | S29: In-Store | T29: Credit Card | U29: Refunded | V29: 10 | W29: 104.42 | X29: 45616 | Y29: 0.1 | Z29: VIP customer | AA29: High Value | AB29: 1044.2 | AC29: ORD-1122 | AD29: 1122 | AE29: Nov-2024 | AF29: 45626 | AG29: maria
A30: ORD-1122 | B30: 20/11/2024 | C30: MARIA SMITH | D30: East | E30: Sialkot | F30: groceries | G30: Green Tea Pack | H30: In-store | I30: 10 | J30: 104.42 | K30: 0.1 | L30: CC | M30: Refunded | O30: VIP customer | P30: Maria Smith | Q30: East | R30: Groceries | S30: In-Store | T30: Credit Card | U30: Refunded | V30: 10 | W30: 104.42 | X30: 45616 | Y30: 0.1 | Z30: VIP customer | AA30: High Value | AB30: 1044.2 | AC30: ORD-1122 | AD30: 1122 | AE30: Nov-2024 | AF30: 45626 | AG30: maria
A31: ORD-1190 | B31: 2024-06-22 | C31: Fatima Raza | D31: EAST | E31: Multan | F31: groceries | G31: Almonds 500g | H31: Online | I31: 5 | J31: 97.83 | K31: 0.15 | L31: Bank Transfer | M31: Complete | P31: Fatima Raza | Q31: East | R31: Groceries | S31: Online | T31: Bank Transfer | U31: Completed | V31: 5 | W31: 97.83 | X31: 45465 | Y31: 0.15 | AA31: Standard | AB31: 489.15 | AC31: ORD-1190 | AD31: 1190 | AE31: Jun-2024 | AF31: 45473 | AG31: Fatima
A32: ORD-1206 | B32: 2024-11-16 | C32: Bilal Hussain | D32: EAST | E32: Sialkot | F32: groceries | G32: Green Tea Pack | H32: In-store | I32: 8 | J32: 92.01 | K32: 0.05 | L32: cash | M32: Complete | N32: C. Osei | O32: Customer called twice | P32: Bilal Hussain | Q32: East | R32: Groceries | S32: In-Store | T32: Cash | U32: Completed | V32: 8 | W32: 92.01 | X32: 45612 | Y32: 0.05 | Z32: Customer called twice | AA32: Standard | AB32: 736.08 | AC32: ORD-1206 | AD32: 1206 | AE32: Nov-2024 | AF32: 45626 | AG32: bilal
A33: ORD-1129 | B33: 17/07/2024 | C33: Tom Taylor | D33: west | E33: Quetta | F33: groceries | G33: Green Tea Pack | H33: Online | I33: 11 | J33: 63.34 | L33: Bank Transfer | M33: COMPLETED | N33: E. Tanaka | O33: Follow up needed | P33: Tom Taylor | Q33: West | R33: Groceries | S33: Online | T33: Bank Transfer | U33: Completed | V33: 11 | W33: 63.34 | X33: 45490 | Y33: 0 | Z33: Follow up needed | AA33: Standard | AB33: 696.74 | AC33: ORD-1129 | AD33: 1129 | AE33: Jul-2024 | AF33: 45504 | AG33: tom
A34: ORD-1181 | B34: 2024-11-12 | C34: BILAL ALI | D34: west | E34: Quetta | F34: groceries | G34: Olive Oil 1L | H34: Online | I34: 5 | J34: 54.99 | K34: 5% | L34: debit card | M34: COMPLETED | N34: E. Tanaka | O34: Leave at front desk | P34: Bilal Ali | Q34: West | R34: Groceries | S34: Online | T34: Debit Card | U34: Completed | V34: 5 | W34: 54.99 | X34: 45608 | Y34: 5% | Z34: Leave at front desk | AA34: Standard | AB34: 274.95 | AC34: ORD-1181 | AD34: 1181 | AE34: Nov-2024 | AF34: 45626 | AG34: bilal
A35: ORD-1090 | B35: 25/02/2024 | C35: AISHA CLARK | D35: west | F35: groceries | G35: Olive Oil 1L | H35: Online | I35: 10 | J35: 30.02 | K35: 0.15 | L35: CC | M35: PENDING | N35: A. Malik | O35: Follow up needed | P35: Aisha Clark | Q35: West | R35: Groceries | S35: Online | T35: Credit Card | U35: Pending | V35: 10 | W35: 30.02 | X35: 45347 | Y35: 0.15 | Z35: Follow up needed | AA35: Standard | AB35: 300.2 | AC35: ORD-1090 | AD35: 1090 | AE35: Feb-2024 | AF35: 45351 | AG35: Aisha
A36: ORD-1188 | B36: November 05, 2024 | C36: Kate Ahmed | D36: west | E36: Peshawar | F36: groceries | G36: Green Tea Pack | H36: Online | I36: 8 | J36: 13.8 | L36: cash | M36: COMPLETED | N36: A. Malik | O36: Leave at front desk | P36: Kate Ahmed | Q36: West | R36: Groceries | S36: Online | T36: Cash | U36: Completed | V36: 8 | W36: 13.8 | X36: 45601 | Y36: 0 | Z36: Leave at front desk | AA36: Standard | AB36: 110.4 | AC36: ORD-1188 | AD36: 1188 | AE36: Nov-2024 | AF36: 45626 | AG36: Kate
A37: ORD-1119 | B37: 05/04/2024 | C37: michael qureshi | D37: South | E37: Karachi | F37: groceries | G37: Almonds 500g | H37: In-store | I37: 6 | J37: 7.57 | K37: 0.1 | L37: Credit card | M37: COMPLETED | N37: A. Malik | O37: Damaged on arrival - replaced | P37: Michael Qureshi | Q37: South | R37: Groceries | S37: In-Store | T37: Credit Card | U37: Completed | V37: 6 | W37: 7.57 | X37: 45416 | Y37: 0.1 | Z37: Damaged on arrival - replaced | AA37: Standard | AB37: 45.42 | AC37: ORD-1119 | AD37: 1119 | AE37: May-2024 | AF37: 45443 | AG37: Michael
A38: ORD-1135 | B38: 10/22/2024 | C38: Aisha Tayloris | D38: north | E38: Islamabad | F38: Grocery | G38: Basmati Rice 5kg | H38: In-store | I38: 7 | J38: 217.67 | L38: CC | M38: cancelled | N38: E. Tanaka | O38: Damaged on arrival - replaced | P38: Aisha Tayloris | Q38: North | R38: Groceries | S38: In-Store | T38: Credit Card | U38: Cancelled | V38: 7 | W38: 217.67 | X38: 45587 | Y38: 0 | Z38: Damaged on arrival - replaced | AA38: High Value | AB38: 1523.69 | AC38: ORD-1135 | AD38: 1135 | AE38: Oct-2024 | AF38: 45596 | AG38: Aisha
A39: ORD-1135 | B39: 10/22/2024 | C39: AISHA TAYLOR | D39: north | E39: Islamabad | F39: Grocery | G39: Basmati Rice 5kg | H39: In-store | I39: 7 | J39: 217.67 | L39: CC | M39: cancelled | N39: E. Tanaka | O39: Damaged on arrival - replaced | P39: Aisha Taylor | Q39: North | R39: Groceries | S39: In-Store | T39: Credit Card | U39: Cancelled | V39: 7 | W39: 217.67 | X39: 45587 | Y39: 0 | Z39: Damaged on arrival - replaced | AA39: High Value | AB39: 1523.69 | AC39: ORD-1135 | AD39: 1135 | AE39: Oct-2024 | AF39: 45596 | AG39: Aisha
A40: ORD-1229 | B40: 06/24/2024 | C40: priya raza | D40: East | E40: Sialkot | F40: Grocery | G40: Almonds 500g | H40: Online | I40: 3 | J40: 464.64 | K40: 15% | L40: Credit card | M40: COMPLETED | N40: B. Fernandes | P40: Priya Raza | Q40: East | R40: Groceries | S40: Online | T40: Credit Card | U40: Completed | V40: 3 | W40: 464.64 | X40: 45467 | Y40: 15% | AA40: High Value | AB40: 1393.92 | AC40: ORD-1229 | AD40: 1229 | AE40: Jun-2024 | AF40: 45473 | AG40: Priya
A41: ORD-1012 | B41: 2024-04-21 | C41: AISHA GARCIA | D41: north | F41: Grocery | G41: Almonds 500g | H41: In-store | I41: 7 | J41: 366.6 | K41: 15% | L41: Credit card | M41: Complete | N41: C. Osei | O41: Bulk order - business account | P41: Aisha Garcia | Q41: North | R41: Groceries | S41: In-Store | T41: Credit Card | U41: Completed | V41: 7 | W41: 366.6 | X41: 45403 | Y41: 15% | Z41: Bulk order - business account | AA41: High Value | AB41: 2566.2 | AC41: ORD-1012 | AD41: 1012 | AE41: Apr-2024 | AF41: 45412 | AG41: Aisha
...

Sheet Pivot_RevenueByCategory
A3: Sum of Revenue | B3: Column Labels
A4: Row Labels | B4: In-Store | C4: Online
A5: Furniture | B5: 33823.73 | C5: 53959.13
A6: Clothing | B6: 50919.96 | C6: 29750.89
A7: Stationery | B7: 35566.63 | C7: 37437.71
A8: Groceries | B8: 45323.09 | C8: 24164.61
A9: Electronics | B9: 52611.52 | C9: 16397.65
A10: Grand Total | B10: 218244.93 | C10: 161709.99

Sheet Pivot_RegionSummary
A3: Row Labels | B3: Order Count | C3: Average Order Value
A4: East | B4: 72 | C4: 1702.2501
A5: North | B5: 58 | C5: 1405.2457
A6: South | B6: 52 | C6: 1796.5035
A7: West | B7: 62 | C7: 1330.169
A8: Grand Total | B8: 244 | C8: 1557.1923

Sheet Pivot_PaymentMethod
A1: OrderStatus_Cleaned | B1: Completed
A3: Row Labels | B3: Sum of Revenue
A4: CREDIT CARD | B4: 31328.87
A5: cash | B5: 28938.38
A6: debit card | B6: 19855.3
A7: Cash | B7: 14903.96
A8: Bank Transfer | B8: 13382.45
A9: CC | B9: 10555.29
A10: Credit card | B10: 6195.98
A11: Grand Total | B11: 125160.23

Sheet Pivot_MonthlyTrend
A3: Row Labels | B3: Sum of Revenue | C3: OrderCount
A4: 2024 | B4: 379954.92 | C4: 244
A5: Jan | B5: 17245.77 | C5: 10
A6: Feb | B6: 31669.22 | C6: 17
A7: Mar | B7: 40626.09 | C7: 23
A8: Apr | B8: 24408.01 | C8: 20
A9: May | B9: 26801.61 | C9: 24
A10: Jun | B10: 32460.67 | C10: 22
A11: Jul | B11: 42306.64 | C11: 23
A12: Aug | B12: 60793.1 | C12: 28
A13: Sep | B13: 24267.75 | C13: 14
A14: Oct | B14: 24898.75 | C14: 23
A15: Nov | B15: 15474.37 | C15: 16
... A17: Grand Total | B17: 379954.92 | C17: 244

Sheet Sparklines_Practice
A1: SalesRep | B1: 45292 | C1: 45323 | D1: 45352 | E1: 45383 | F1: 45413 | G1: 45444 | H1: 45474 | I1: 45505 | J1: 45536 | K1: 45566 | L1: 45597 | M1: 45627 | N1: Trend
A2: {=_xlfn._xlws.SORT(_xlfn.UNIQUE(_xlfn._xlws.FILTER(tblOrders[SalesRep],tblOrders[SalesRep]<>"")))} -> A. Malik | B2: =SUMIFS(Orders_Raw!$AB$2:$AB$245,Orders_Raw!$N$2:$N$245,$A2,Orders_Raw!$AE$2:$AE$245,TEXT(B$1,"mmm-yyyy")) -> 1381.65 | C2: =SUMIFS(Orders_Raw!$AB$2:$AB$245,Orders_Raw!$N$2:$N$245,$A2,Orders_Raw!$AE$2:$AE$245,TEXT(C$1,"mmm-yyyy")) -> 9588.01 | D2: =SUMIFS(Orders_Raw!$AB$2:$AB$245,Orders_Raw!$N$2:$N$245,$A2,Orders_Raw!$AE$2:$AE$245,TEXT(D$1,"mmm-yyyy")) -> 9914.5 | E2: =SUMIFS(Orders_Raw!$AB$2:$AB$245,Orders_Raw!$N$2:$N$245,$A2,Orders_Raw!$AE$2:$AE$245,TEXT(E$1,"mmm-yyyy")) -> 0 | F2: =SUMIFS(Orders_Raw!$AB$2:$AB$245,Orders_Raw!$N$2:$N$245,$A2,Orders_Raw!$AE$2:$AE$245,TEXT(F$1,"mmm-yyyy")) -> 5807.2 | G2: =SUMIFS(Orders_Raw!$AB$2:$AB$245,Orders_Raw!$N$2:$N$245,$A2,Orders_Raw!$AE$2:$AE$245,TEXT(G$1,"mmm-yyyy")) -> 5442.18 | H2: =SUMIFS(Orders_Raw!$AB$2:$AB$245,Orders_Raw!$N$2:$N$245,$A2,Orders_Raw!$AE$2:$AE$245,TEXT(H$1,"mmm-yyyy")) -> 10755.06 | I2: =SUMIFS(Orders_Raw!$AB$2:$AB$245,Orders_Raw!$N$2:$N$245,$A2,Orders_Raw!$AE$2:$AE$245,TEXT(I$1,"mmm-yyyy")) -> 5151.58 | ... M2: =SUMIFS(Orders_Raw!$AB$2:$AB$245,Orders_Raw!$N$2:$N$245,$A2,Orders_Raw!$AE$2:$AE$245,TEXT(M$1,"mmm-yyyy")) -> 2232
A3: B. Fernandes | B3: =SUMIFS(Orders_Raw!$AB$2:$AB$245,Orders_Raw!$N$2:$N$245,$A3,Orders_Raw!$AE$2:$AE$245,TEXT(B$1,"mmm-yyyy")) -> 4630.91 | C3: =SUMIFS(Orders_Raw!$AB$2:$AB$245,Orders_Raw!$N$2:$N$245,$A3,Orders_Raw!$AE$2:$AE$245,TEXT(C$1,"mmm-yyyy")) -> 2023.26 | D3: =SUMIFS(Orders_Raw!$AB$2:$AB$245,Orders_Raw!$N$2:$N$245,$A3,Orders_Raw!$AE$2:$AE$245,TEXT(D$1,"mmm-yyyy")) -> 9445.6 | E3: =SUMIFS(Orders_Raw!$AB$2:$AB$245,Orders_Raw!$N$2:$N$245,$A3,Orders_Raw!$AE$2:$AE$245,TEXT(E$1,"mmm-yyyy")) -> 4572.05 | F3: =SUMIFS(Orders_Raw!$AB$2:$AB$245,Orders_Raw!$N$2:$N$245,$A3,Orders_Raw!$AE$2:$AE$245,TEXT(F$1,"mmm-yyyy")) -> 10664.14 | G3: =SUMIFS(Orders_Raw!$AB$2:$AB$245,Orders_Raw!$N$2:$N$245,$A3,Orders_Raw!$AE$2:$AE$245,TEXT(G$1,"mmm-yyyy")) -> 1393.92 | H3: =SUMIFS(Orders_Raw!$AB$2:$AB$245,Orders_Raw!$N$2:$N$245,$A3,Orders_Raw!$AE$2:$AE$245,TEXT(H$1,"mmm-yyyy")) -> 1767.5 | I3: =SUMIFS(Orders_Raw!$AB$2:$AB$245,Orders_Raw!$N$2:$N$245,$A3,Orders_Raw!$AE$2:$AE$245,TEXT(I$1,"mmm-yyyy")) -> 2541.45 | ... M3: =SUMIFS(Orders_Raw!$AB$2:$AB$245,Orders_Raw!$N$2:$N$245,$A3,Orders_Raw!$AE$2:$AE$245,TEXT(M$1,"mmm-yyyy")) -> 3953.16
A4: C. Osei | B4: =SUMIFS(Orders_Raw!$AB$2:$AB$245,Orders_Raw!$N$2:$N$245,$A4,Orders_Raw!$AE$2:$AE$245,TEXT(B$1,"mmm-yyyy")) -> 0 | C4: =SUMIFS(Orders_Raw!$AB$2:$AB$245,Orders_Raw!$N$2:$N$245,$A4,Orders_Raw!$AE$2:$AE$245,TEXT(C$1,"mmm-yyyy")) -> 1950.03 | D4: =SUMIFS(Orders_Raw!$AB$2:$AB$245,Orders_Raw!$N$2:$N$245,$A4,Orders_Raw!$AE$2:$AE$245,TEXT(D$1,"mmm-yyyy")) -> 7267.12 | E4: =SUMIFS(Orders_Raw!$AB$2:$AB$245,Orders_Raw!$N$2:$N$245,$A4,Orders_Raw!$AE$2:$AE$245,TEXT(E$1,"mmm-yyyy")) -> 7615.4 | F4: =SUMIFS(Orders_Raw!$AB$2:$AB$245,Orders_Raw!$N$2:$N$245,$A4,Orders_Raw!$AE$2:$AE$245,TEXT(F$1,"mmm-yyyy")) -> 583.64 | G4: =SUMIFS(Orders_Raw!$AB$2:$AB$245,Orders_Raw!$N$2:$N$245,$A4,Orders_Raw!$AE$2:$AE$245,TEXT(G$1,"mmm-yyyy")) -> 1963.2 | H4: =SUMIFS(Orders_Raw!$AB$2:$AB$245,Orders_Raw!$N$2:$N$245,$A4,Orders_Raw!$AE$2:$AE$245,TEXT(H$1,"mmm-yyyy")) -> 4404.68 | I4: =SUMIFS(Orders_Raw!$AB$2:$AB$245,Orders_Raw!$N$2:$N$245,$A4,Orders_Raw!$AE$2:$AE$245,TEXT(I$1,"mmm-yyyy")) -> 20851.11 | ... M4: =SUMIFS(Orders_Raw!$AB$2:$AB$245,Orders_Raw!$N$2:$N$245,$A4,Orders_Raw!$AE$2:$AE$245,TEXT(M$1,"mmm-yyyy")) -> 8104.84
A5: D. Iqbal | B5: =SUMIFS(Orders_Raw!$AB$2:$AB$245,Orders_Raw!$N$2:$N$245,$A5,Orders_Raw!$AE$2:$AE$245,TEXT(B$1,"mmm-yyyy")) -> 3509.43 | C5: =SUMIFS(Orders_Raw!$AB$2:$AB$245,Orders_Raw!$N$2:$N$245,$A5,Orders_Raw!$AE$2:$AE$245,TEXT(C$1,"mmm-yyyy")) -> 4329.61 | D5: =SUMIFS(Orders_Raw!$AB$2:$AB$245,Orders_Raw!$N$2:$N$245,$A5,Orders_Raw!$AE$2:$AE$245,TEXT(D$1,"mmm-yyyy")) -> 5993.34 | E5: =SUMIFS(Orders_Raw!$AB$2:$AB$245,Orders_Raw!$N$2:$N$245,$A5,Orders_Raw!$AE$2:$AE$245,TEXT(E$1,"mmm-yyyy")) -> 1896.03 | F5: =SUMIFS(Orders_Raw!$AB$2:$AB$245,Orders_Raw!$N$2:$N$245,$A5,Orders_Raw!$AE$2:$AE$245,TEXT(F$1,"mmm-yyyy")) -> 4217.37 | G5: =SUMIFS(Orders_Raw!$AB$2:$AB$245,Orders_Raw!$N$2:$N$245,$A5,Orders_Raw!$AE$2:$AE$245,TEXT(G$1,"mmm-yyyy")) -> 6663.1 | H5: =SUMIFS(Orders_Raw!$AB$2:$AB$245,Orders_Raw!$N$2:$N$245,$A5,Orders_Raw!$AE$2:$AE$245,TEXT(H$1,"mmm-yyyy")) -> 5673.96 | I5: =SUMIFS(Orders_Raw!$AB$2:$AB$245,Orders_Raw!$N$2:$N$245,$A5,Orders_Raw!$AE$2:$AE$245,TEXT(I$1,"mmm-yyyy")) -> 7491.19 | ... M5: =SUMIFS(Orders_Raw!$AB$2:$AB$245,Orders_Raw!$N$2:$N$245,$A5,Orders_Raw!$AE$2:$AE$245,TEXT(M$1,"mmm-yyyy")) -> 7976.01
A6: E. Tanaka | B6: =SUMIFS(Orders_Raw!$AB$2:$AB$245,Orders_Raw!$N$2:$N$245,$A6,Orders_Raw!$AE$2:$AE$245,TEXT(B$1,"mmm-yyyy")) -> 7723.78 | C6: =SUMIFS(Orders_Raw!$AB$2:$AB$245,Orders_Raw!$N$2:$N$245,$A6,Orders_Raw!$AE$2:$AE$245,TEXT(C$1,"mmm-yyyy")) -> 4282.38 | D6: =SUMIFS(Orders_Raw!$AB$2:$AB$245,Orders_Raw!$N$2:$N$245,$A6,Orders_Raw!$AE$2:$AE$245,TEXT(D$1,"mmm-yyyy")) -> 6252.38 | E6: =SUMIFS(Orders_Raw!$AB$2:$AB$245,Orders_Raw!$N$2:$N$245,$A6,Orders_Raw!$AE$2:$AE$245,TEXT(E$1,"mmm-yyyy")) -> 4045.13 | F6: =SUMIFS(Orders_Raw!$AB$2:$AB$245,Orders_Raw!$N$2:$N$245,$A6,Orders_Raw!$AE$2:$AE$245,TEXT(F$1,"mmm-yyyy")) -> 4209.77 | G6: =SUMIFS(Orders_Raw!$AB$2:$AB$245,Orders_Raw!$N$2:$N$245,$A6,Orders_Raw!$AE$2:$AE$245,TEXT(G$1,"mmm-yyyy")) -> 11035.68 | H6: =SUMIFS(Orders_Raw!$AB$2:$AB$245,Orders_Raw!$N$2:$N$245,$A6,Orders_Raw!$AE$2:$AE$245,TEXT(H$1,"mmm-yyyy")) -> 10756.58 | I6: =SUMIFS(Orders_Raw!$AB$2:$AB$245,Orders_Raw!$N$2:$N$245,$A6,Orders_Raw!$AE$2:$AE$245,TEXT(I$1,"mmm-yyyy")) -> 9685.67 | ... M6: =SUMIFS(Orders_Raw!$AB$2:$AB$245,Orders_Raw!$N$2:$N$245,$A6,Orders_Raw!$AE$2:$AE$245,TEXT(M$1,"mmm-yyyy")) -> 7998.78
J15: =COUNTIFS(tblOrders[SalesRep],$A2,tblOrders[MonthLabel],B$1) -> 1

Sheet Pivot_AvgDiscount
A3: Row Labels | B3: Average of Discount_Clean
A4: Stationery | B4: 0.060869565
A5: Furniture | B5: 0.059302326
A6: Electronics | B6: 0.05625
A7: Groceries | B7: 0.052631579
A8: Clothing | B8: 0.04893617
A9: Grand Total | B9: 0.055582524

Sheet Pivot_SalesRepCount
A1: OrderStatus_Cleaned | B1: (Multiple Items)
A3: Row Labels | B3: Count of OrderID
A4: A. Malik | B4: 31
A5: B. Fernandes | B5: 29
A6: C. Osei | B6: 32
A7: D. Iqbal | B7: 27
A8: E. Tanaka | B8: 35
A9: (blank) | B9: 26
A10: Grand Total | B10: 180

Sheet Pivot_RegionCategory
A3: Row Labels | B3: Sum of Revenue
A4: East | B4: 122562.01
A5: Clothing | B5: 48513.41
A6: Electronics | B6: 18793.25
A7: Furniture | B7: 11400.92
A8: Groceries | B8: 20535.17
A9: Stationery | B9: 23319.26
A10: North | B10: 81504.25
A11: Clothing | B11: 10126.17
A12: Electronics | B12: 21763.41
A13: Furniture | B13: 16882.46
A14: Groceries | B14: 17248.38
A15: Stationery | B15: 15483.83
... A28: Grand Total | B28: 379954.92

Sheet Sheet1
A1: Region_Clean | B1: (All)
A3: Row Labels | B3: Sum of Revenue
A4: In-Store | B4: 218244.93
A5: Online | B5: 161709.99
A6: Grand Total | B6: 379954.92

Sheet Pivot_SalesRepRevenue
A3: Row Labels | B3: Sum of Revenue
A4: E. Tanaka | B4: 76962.02
A5: (blank) | B5: 70422.16
A6: C. Osei | B6: 65661.72
A7: A. Malik | B7: 61591.62
A8: D. Iqbal | B8: 58939.54
A9: B. Fernandes | B9: 46377.86
A10: Grand Total | B10: 379954.92

Sheet Pivot_StatusCount
A1: Channel_Clean | B1: Online
A3: Row Labels | B3: Count of OrderID
A4: Cancelled | B4: 22
A5: Completed | B5: 35
A6: Pending | B6: 27
A7: Refunded | B7: 20
A8: Grand Total | B8: 104

Sheet Pivot_RevenueDiscount
A3: Row Labels | B3: Sum of Revenue | C3: Average of Discount_Numeric
A4: In-Store | B4: 218244.93 | C4: 0.061071429
A5: Online | B5: 161709.99 | C5: 0.069711538
A6: Grand Total | B6: 379954.92 | C6: 0.064754098

Sheet Category_Sparklines
A1: Category | B1: 45292 | C1: 45323 | D1: 45352 | E1: 45383 | F1: 45413 | G1: 45444 | H1: 45474 | I1: 45505 | J1: 45536 | K1: 45566 | L1: 45597 | M1: 45627 | N1: Trend
A2: Electronics | B2: =SUMIFS(Orders_Raw!$AB$2:$AB$245,Orders_Raw!$R$2:$R$245,$A2,Orders_Raw!$AE$2:$AE$245,B$1) -> 4818.3 | C2: =SUMIFS(Orders_Raw!$AB$2:$AB$245,Orders_Raw!$R$2:$R$245,$A2,Orders_Raw!$AE$2:$AE$245,C$1) -> 7378.98 | D2: =SUMIFS(Orders_Raw!$AB$2:$AB$245,Orders_Raw!$R$2:$R$245,$A2,Orders_Raw!$AE$2:$AE$245,D$1) -> 6274.95 | E2: =SUMIFS(Orders_Raw!$AB$2:$AB$245,Orders_Raw!$R$2:$R$245,$A2,Orders_Raw!$AE$2:$AE$245,E$1) -> 9618.08 | F2: =SUMIFS(Orders_Raw!$AB$2:$AB$245,Orders_Raw!$R$2:$R$245,$A2,Orders_Raw!$AE$2:$AE$245,F$1) -> 141.82 | G2: =SUMIFS(Orders_Raw!$AB$2:$AB$245,Orders_Raw!$R$2:$R$245,$A2,Orders_Raw!$AE$2:$AE$245,G$1) -> 2831.64 | H2: =SUMIFS(Orders_Raw!$AB$2:$AB$245,Orders_Raw!$R$2:$R$245,$A2,Orders_Raw!$AE$2:$AE$245,H$1) -> 6060.7 | I2: =SUMIFS(Orders_Raw!$AB$2:$AB$245,Orders_Raw!$R$2:$R$245,$A2,Orders_Raw!$AE$2:$AE$245,I$1) -> 5259.06 | ... M2: =SUMIFS(Orders_Raw!$AB$2:$AB$245,Orders_Raw!$R$2:$R$245,$A2,Orders_Raw!$AE$2:$AE$245,M$1) -> 14844.93
A3: Furniture | B3: =SUMIFS(Orders_Raw!$AB$2:$AB$245,Orders_Raw!$R$2:$R$245,$A3,Orders_Raw!$AE$2:$AE$245,B$1) -> 4069.35 | C3: =SUMIFS(Orders_Raw!$AB$2:$AB$245,Orders_Raw!$R$2:$R$245,$A3,Orders_Raw!$AE$2:$AE$245,C$1) -> 6317.43 | D3: =SUMIFS(Orders_Raw!$AB$2:$AB$245,Orders_Raw!$R$2:$R$245,$A3,Orders_Raw!$AE$2:$AE$245,D$1) -> 13376.87 | E3: =SUMIFS(Orders_Raw!$AB$2:$AB$245,Orders_Raw!$R$2:$R$245,$A3,Orders_Raw!$AE$2:$AE$245,E$1) -> 978.65 | F3: =SUMIFS(Orders_Raw!$AB$2:$AB$245,Orders_Raw!$R$2:$R$245,$A3,Orders_Raw!$AE$2:$AE$245,F$1) -> 7946.7 | G3: =SUMIFS(Orders_Raw!$AB$2:$AB$245,Orders_Raw!$R$2:$R$245,$A3,Orders_Raw!$AE$2:$AE$245,G$1) -> 4700.62 | H3: =SUMIFS(Orders_Raw!$AB$2:$AB$245,Orders_Raw!$R$2:$R$245,$A3,Orders_Raw!$AE$2:$AE$245,H$1) -> 5616.64 | I3: =SUMIFS(Orders_Raw!$AB$2:$AB$245,Orders_Raw!$R$2:$R$245,$A3,Orders_Raw!$AE$2:$AE$245,I$1) -> 17151.18 | ... M3: =SUMIFS(Orders_Raw!$AB$2:$AB$245,Orders_Raw!$R$2:$R$245,$A3,Orders_Raw!$AE$2:$AE$245,M$1) -> 5789.61
A4: Clothing | B4: =SUMIFS(Orders_Raw!$AB$2:$AB$245,Orders_Raw!$R$2:$R$245,$A4,Orders_Raw!$AE$2:$AE$245,B$1) -> 94.52 | C4: =SUMIFS(Orders_Raw!$AB$2:$AB$245,Orders_Raw!$R$2:$R$245,$A4,Orders_Raw!$AE$2:$AE$245,C$1) -> 652.6 | D4: =SUMIFS(Orders_Raw!$AB$2:$AB$245,Orders_Raw!$R$2:$R$245,$A4,Orders_Raw!$AE$2:$AE$245,D$1) -> 10307.76 | E4: =SUMIFS(Orders_Raw!$AB$2:$AB$245,Orders_Raw!$R$2:$R$245,$A4,Orders_Raw!$AE$2:$AE$245,E$1) -> 3625.76 | F4: =SUMIFS(Orders_Raw!$AB$2:$AB$245,Orders_Raw!$R$2:$R$245,$A4,Orders_Raw!$AE$2:$AE$245,F$1) -> 4625.76 | G4: =SUMIFS(Orders_Raw!$AB$2:$AB$245,Orders_Raw!$R$2:$R$245,$A4,Orders_Raw!$AE$2:$AE$245,G$1) -> 13994.53 | H4: =SUMIFS(Orders_Raw!$AB$2:$AB$245,Orders_Raw!$R$2:$R$245,$A4,Orders_Raw!$AE$2:$AE$245,H$1) -> 12641.68 | I4: =SUMIFS(Orders_Raw!$AB$2:$AB$245,Orders_Raw!$R$2:$R$245,$A4,Orders_Raw!$AE$2:$AE$245,I$1) -> 25647.32 | ... M4: =SUMIFS(Orders_Raw!$AB$2:$AB$245,Orders_Raw!$R$2:$R$245,$A4,Orders_Raw!$AE$2:$AE$245,M$1) -> 5591.58
A5: Groceries | B5: =SUMIFS(Orders_Raw!$AB$2:$AB$245,Orders_Raw!$R$2:$R$245,$A5,Orders_Raw!$AE$2:$AE$245,B$1) -> 1592.4 | C5: =SUMIFS(Orders_Raw!$AB$2:$AB$245,Orders_Raw!$R$2:$R$245,$A5,Orders_Raw!$AE$2:$AE$245,C$1) -> 7683.28 | D5: =SUMIFS(Orders_Raw!$AB$2:$AB$245,Orders_Raw!$R$2:$R$245,$A5,Orders_Raw!$AE$2:$AE$245,D$1) -> 8780.09 | E5: =SUMIFS(Orders_Raw!$AB$2:$AB$245,Orders_Raw!$R$2:$R$245,$A5,Orders_Raw!$AE$2:$AE$245,E$1) -> 3061.8 | F5: =SUMIFS(Orders_Raw!$AB$2:$AB$245,Orders_Raw!$R$2:$R$245,$A5,Orders_Raw!$AE$2:$AE$245,F$1) -> 4554.3 | G5: =SUMIFS(Orders_Raw!$AB$2:$AB$245,Orders_Raw!$R$2:$R$245,$A5,Orders_Raw!$AE$2:$AE$245,G$1) -> 5302.47 | H5: =SUMIFS(Orders_Raw!$AB$2:$AB$245,Orders_Raw!$R$2:$R$245,$A5,Orders_Raw!$AE$2:$AE$245,H$1) -> 9610.21 | I5: =SUMIFS(Orders_Raw!$AB$2:$AB$245,Orders_Raw!$R$2:$R$245,$A5,Orders_Raw!$AE$2:$AE$245,I$1) -> 10416.66 | ... M5: =SUMIFS(Orders_Raw!$AB$2:$AB$245,Orders_Raw!$R$2:$R$245,$A5,Orders_Raw!$AE$2:$AE$245,M$1) -> 8181.86
A6: Stationery | B6: =SUMIFS(Orders_Raw!$AB$2:$AB$245,Orders_Raw!$R$2:$R$245,$A6,Orders_Raw!$AE$2:$AE$245,B$1) -> 6671.2 | C6: =SUMIFS(Orders_Raw!$AB$2:$AB$245,Orders_Raw!$R$2:$R$245,$A6,Orders_Raw!$AE$2:$AE$245,C$1) -> 9636.93 | D6: =SUMIFS(Orders_Raw!$AB$2:$AB$245,Orders_Raw!$R$2:$R$245,$A6,Orders_Raw!$AE$2:$AE$245,D$1) -> 1886.42 | E6: =SUMIFS(Orders_Raw!$AB$2:$AB$245,Orders_Raw!$R$2:$R$245,$A6,Orders_Raw!$AE$2:$AE$245,E$1) -> 7123.72 | F6: =SUMIFS(Orders_Raw!$AB$2:$AB$245,Orders_Raw!$R$2:$R$245,$A6,Orders_Raw!$AE$2:$AE$245,F$1) -> 9533.03 | G6: =SUMIFS(Orders_Raw!$AB$2:$AB$245,Orders_Raw!$R$2:$R$245,$A6,Orders_Raw!$AE$2:$AE$245,G$1) -> 5631.41 | H6: =SUMIFS(Orders_Raw!$AB$2:$AB$245,Orders_Raw!$R$2:$R$245,$A6,Orders_Raw!$AE$2:$AE$245,H$1) -> 8377.41 | I6: =SUMIFS(Orders_Raw!$AB$2:$AB$245,Orders_Raw!$R$2:$R$245,$A6,Orders_Raw!$AE$2:$AE$245,I$1) -> 2318.88 | ... M6: =SUMIFS(Orders_Raw!$AB$2:$AB$245,Orders_Raw!$R$2:$R$245,$A6,Orders_Raw!$AE$2:$AE$245,M$1) -> 4594.96

Sheet Orders_Raw
A1: OrderID | B1: OrderDate | C1: CustomerName | D1: Region | E1: City | F1: Category | G1: Product | H1: Channel | I1: Quantity | J1: UnitPrice | K1: Discount | L1: PaymentMethod | M1: OrderStatus | N1: SalesRep | O1: Notes | P1: CustomerName_Clean | Q1: Region_Clean | R1: Category_Clean | S1: Channel_Clean | T1: PaymentMethod_Clean | U1: OrderStatus_Cleaned | V1: Quantity_Clean | W1: UnitPrice_Clean | X1: OrderDate_Clean | Y1: Discount_Clean | Z1: Notes_Clean | AA1: HighValueFlag | AB1: Revenue | AC1: OrderID_Key | AD1: OrderNumber | AE1: MonthLabel | AF1: MonthEndDate | AG1: FirstName | AH1: Discount_Numeric
A2: ORD-1109 | B2: 10/02/2024 | C2: Chen Malik | D2: west | E2: Quetta | F2: Furniture | G2: Office Chair | H2: In-store | I2: 7 | J2: $280.86 | L2: Credit card | M2: cancelled | P2: =PROPER(TRIM(C2)) -> Chen Malik | Q2: =IF(OR(PROPER(TRIM(tblOrders[[#This Row],[Region]]))="Nort",PROPER(TRIM(tblOrders[[#This Row],[Region]]))="Northh"),"North",PROPER(TRIM(tblOrders[[#This Row],[Region]]))) -> West | R2: =IF(PROPER(TRIM(F2))="Cloth Ing","Clothing",IF(PROPER(TRIM(F2))="Electronic","Electronics",IF(PROPER(TRIM(F2))="Grocery","Groceries",SUBSTITUTE(PROPER(TRIM(F2)),"Stationary","Stationery")))) -> Furniture | S2: =IF(LOWER(TRIM(H2))="online","Online",IF(OR(LOWER(TRIM(H2))="in-store",LOWER(TRIM(H2))="in store",LOWER(TRIM(H2))="instore"),"In-Store",PROPER(TRIM(H2)))) -> In-Store | T2: =IF(UPPER(TRIM(L2))="CC","Credit Card",PROPER(TRIM(L2))) -> Credit Card | U2: =IF(PROPER(TRIM(M2))="Complete","Completed",IF(PROPER(TRIM(M2))="Canceled","Cancelled",PROPER(TRIM(M2)))) -> Cancelled | V2: =IFERROR(VALUE(TRIM(I2)),"") -> 7 | W2: =IFERROR(VALUE(SUBSTITUTE(TRIM(J2),"$","")),"") -> 280.86 | X2: =IFERROR(IF(ISNUMBER(tblOrders[[#This Row],[OrderDate]]),tblOrders[[#This Row],[OrderDate]],IFERROR(DATEVALUE(tblOrders[[#This Row],[OrderDate]]),DATE(IF(LEN(TRIM(tblOrders[[#This Row],[OrderDate]]))=8,2000+VALUE(RIGHT(TRIM(tblOrders[[#This Row],[OrderDate]]),2)),VALUE(RIGHT(TRIM(tblOrders[[#This Row],[OrderDate]]),4))),VALUE(MID(TRIM(tblOrders[[#This Row],[OrderDate]]),4,2)),VALUE(LEFT(TRIM(tblOrders[[#This Row],[OrderDate]]),2))))),"CHECK MANUALLY") -> 45567 | Y2: =IF(K2="",0,K2) -> 0 | Z2: =TRIM(CLEAN(tblOrders[[#This Row],[Notes]])) | AA2: =IF(OR(V2="",W2=""),"Review",IF(V2*W2>=1000,"High Value","Standard")) -> High Value | AB2: =IF(OR(tblOrders[[#This Row],[Quantity_Clean]]="",tblOrders[[#This Row],[UnitPrice_Clean]]=""),0,tblOrders[[#This Row],[Quantity_Clean]]*tblOrders[[#This Row],[UnitPrice_Clean]]) -> 1966.02 | AC2: =UPPER(TRIM(tblOrders[[#This Row],[OrderID]])) -> ORD-1109 | AD2: =VALUE(RIGHT(tblOrders[[#This Row],[OrderID]],4)) -> 1109 | AE2: =TEXT(tblOrders[[#This Row],[OrderDate_Clean]],"mmm-yyyy") -> Oct-2024 | AF2: =EOMONTH(tblOrders[[#This Row],[OrderDate_Clean]],0) -> 45596 | AG2: Chen | AH2: =IF(tblOrders[[#This Row],[Discount]]="",0,IF(ISNUMBER(tblOrders[[#This Row],[Discount]]),tblOrders[[#This Row],[Discount]],VALUE(SUBSTITUTE(TRIM(tblOrders[[#This Row],[Discount]]),"%",""))/100)) -> 0
A3: ORD-1105 | B3: 03/01/2024 | C3: Grace Khan | D3: West | E3: Peshawar | F3: Furniture | G3: Bookshelf | H3: In Store | I3: 8 | J3: 453.85 | K3: 20% | L3: CREDIT CARD | M3: PENDING | N3: C. Osei | O3: Bulk order - business account | P3: =PROPER(TRIM(C3)) -> Grace Khan | Q3: =IF(OR(PROPER(TRIM(tblOrders[[#This Row],[Region]]))="Nort",PROPER(TRIM(tblOrders[[#This Row],[Region]]))="Northh"),"North",PROPER(TRIM(tblOrders[[#This Row],[Region]]))) -> West | R3: =IF(PROPER(TRIM(F3))="Cloth Ing","Clothing",IF(PROPER(TRIM(F3))="Electronic","Electronics",IF(PROPER(TRIM(F3))="Grocery","Groceries",SUBSTITUTE(PROPER(TRIM(F3)),"Stationary","Stationery")))) -> Furniture | S3: =IF(LOWER(TRIM(H3))="online","Online",IF(OR(LOWER(TRIM(H3))="in-store",LOWER(TRIM(H3))="in store",LOWER(TRIM(H3))="instore"),"In-Store",PROPER(TRIM(H3)))) -> In-Store | T3: =IF(UPPER(TRIM(L3))="CC","Credit Card",PROPER(TRIM(L3))) -> Credit Card | U3: =IF(PROPER(TRIM(M3))="Complete","Completed",IF(PROPER(TRIM(M3))="Canceled","Cancelled",PROPER(TRIM(M3)))) -> Pending | V3: =IFERROR(VALUE(TRIM(I3)),"") -> 8 | W3: =IFERROR(VALUE(SUBSTITUTE(TRIM(J3),"$","")),"") -> 453.85 | X3: =IFERROR(IF(ISNUMBER(tblOrders[[#This Row],[OrderDate]]),tblOrders[[#This Row],[OrderDate]],IFERROR(DATEVALUE(tblOrders[[#This Row],[OrderDate]]),DATE(IF(LEN(TRIM(tblOrders[[#This Row],[OrderDate]]))=8,2000+VALUE(RIGHT(TRIM(tblOrders[[#This Row],[OrderDate]]),2)),VALUE(RIGHT(TRIM(tblOrders[[#This Row],[OrderDate]]),4))),VALUE(MID(TRIM(tblOrders[[#This Row],[OrderDate]]),4,2)),VALUE(LEFT(TRIM(tblOrders[[#This Row],[OrderDate]]),2))))),"CHECK MANUALLY") -> 45352 | Y3: =IF(K3="",0,K3) -> 20% | Z3: =TRIM(CLEAN(tblOrders[[#This Row],[Notes]])) -> Bulk order - business account | AA3: =IF(OR(V3="",W3=""),"Review",IF(V3*W3>=1000,"High Value","Standard")) -> High Value | AB3: =IF(OR(tblOrders[[#This Row],[Quantity_Clean]]="",tblOrders[[#This Row],[UnitPrice_Clean]]=""),0,tblOrders[[#This Row],[Quantity_Clean]]*tblOrders[[#This Row],[UnitPrice_Clean]]) -> 3630.8 | AC3: =UPPER(TRIM(tblOrders[[#This Row],[OrderID]])) -> ORD-1105 | AD3: =VALUE(RIGHT(tblOrders[[#This Row],[OrderID]],4)) -> 1105 | AE3: =TEXT(tblOrders[[#This Row],[OrderDate_Clean]],"mmm-yyyy") -> Mar-2024 | AF3: =EOMONTH(tblOrders[[#This Row],[OrderDate_Clean]],0) -> 45382 | AG3: Grace | AH3: =IF(tblOrders[[#This Row],[Discount]]="",0,IF(ISNUMBER(tblOrders[[#This Row],[Discount]]),tblOrders[[#This Row],[Discount]],VALUE(SUBSTITUTE(TRIM(tblOrders[[#This Row],[Discount]]),"%",""))/100)) -> 0.2
A4: ORD-1200 | B4: 13/01/2024 | C4: Grace Smith | D4: north | E4: Faisalabad | F4: Furniture | G4: Office Chair | H4: Online | I4: 9 | J4: 439.93 | K4: 0 | L4: Bank Transfer | M4: PENDING | N4: B. Fernandes | P4: =PROPER(TRIM(C4)) -> Grace Smith | Q4: =IF(OR(PROPER(TRIM(tblOrders[[#This Row],[Region]]))="Nort",PROPER(TRIM(tblOrders[[#This Row],[Region]]))="Northh"),"North",PROPER(TRIM(tblOrders[[#This Row],[Region]]))) -> North | R4: =IF(PROPER(TRIM(F4))="Cloth Ing","Clothing",IF(PROPER(TRIM(F4))="Electronic","Electronics",IF(PROPER(TRIM(F4))="Grocery","Groceries",SUBSTITUTE(PROPER(TRIM(F4)),"Stationary","Stationery")))) -> Furniture | S4: =IF(LOWER(TRIM(H4))="online","Online",IF(OR(LOWER(TRIM(H4))="in-store",LOWER(TRIM(H4))="in store",LOWER(TRIM(H4))="instore"),"In-Store",PROPER(TRIM(H4)))) -> Online | T4: =IF(UPPER(TRIM(L4))="CC","Credit Card",PROPER(TRIM(L4))) -> Bank Transfer | U4: =IF(PROPER(TRIM(M4))="Complete","Completed",IF(PROPER(TRIM(M4))="Canceled","Cancelled",PROPER(TRIM(M4)))) -> Pending | V4: =IFERROR(VALUE(TRIM(I4)),"") -> 9 | W4: =IFERROR(VALUE(SUBSTITUTE(TRIM(J4),"$","")),"") -> 439.93 | X4: =IFERROR(IF(ISNUMBER(tblOrders[[#This Row],[OrderDate]]),tblOrders[[#This Row],[OrderDate]],IFERROR(DATEVALUE(tblOrders[[#This Row],[OrderDate]]),DATE(IF(LEN(TRIM(tblOrders[[#This Row],[OrderDate]]))=8,2000+VALUE(RIGHT(TRIM(tblOrders[[#This Row],[OrderDate]]),2)),VALUE(RIGHT(TRIM(tblOrders[[#This Row],[OrderDate]]),4))),VALUE(MID(TRIM(tblOrders[[#This Row],[OrderDate]]),4,2)),VALUE(LEFT(TRIM(tblOrders[[#This Row],[OrderDate]]),2))))),"CHECK MANUALLY") -> 45304 | Y4: =IF(K4="",0,K4) -> 0 | Z4: =TRIM(CLEAN(tblOrders[[#This Row],[Notes]])) | AA4: =IF(OR(V4="",W4=""),"Review",IF(V4*W4>=1000,"High Value","Standard")) -> High Value | AB4: =IF(OR(tblOrders[[#This Row],[Quantity_Clean]]="",tblOrders[[#This Row],[UnitPrice_Clean]]=""),0,tblOrders[[#This Row],[Quantity_Clean]]*tblOrders[[#This Row],[UnitPrice_Clean]]) -> 3959.37 | AC4: =UPPER(TRIM(tblOrders[[#This Row],[OrderID]])) -> ORD-1200 | AD4: =VALUE(RIGHT(tblOrders[[#This Row],[OrderID]],4)) -> 1200 | AE4: =TEXT(tblOrders[[#This Row],[OrderDate_Clean]],"mmm-yyyy") -> Jan-2024 | AF4: =EOMONTH(tblOrders[[#This Row],[OrderDate_Clean]],0) -> 45322 | AG4: Grace | AH4: =IF(tblOrders[[#This Row],[Discount]]="",0,IF(ISNUMBER(tblOrders[[#This Row],[Discount]]),tblOrders[[#This Row],[Discount]],VALUE(SUBSTITUTE(TRIM(tblOrders[[#This Row],[Discount]]),"%",""))/100)) -> 0
A5: ORD-1212 | B5: 03/28/2024 | C5: David Clark | D5: South | E5: Karachi | F5: Furniture | G5: Sofa Set | H5: Online | I5: 12 | J5: 411.55 | L5: cash | M5: CANCELLED | N5: D. Iqbal | P5: =PROPER(TRIM(C5)) -> David Clark | Q5: =IF(OR(PROPER(TRIM(tblOrders[[#This Row],[Region]]))="Nort",PROPER(TRIM(tblOrders[[#This Row],[Region]]))="Northh"),"North",PROPER(TRIM(tblOrders[[#This Row],[Region]]))) -> South | R5: =IF(PROPER(TRIM(F5))="Cloth Ing","Clothing",IF(PROPER(TRIM(F5))="Electronic","Electronics",IF(PROPER(TRIM(F5))="Grocery","Groceries",SUBSTITUTE(PROPER(TRIM(F5)),"Stationary","Stationery")))) -> Furniture | S5: =IF(LOWER(TRIM(H5))="online","Online",IF(OR(LOWER(TRIM(H5))="in-store",LOWER(TRIM(H5))="in store",LOWER(TRIM(H5))="instore"),"In-Store",PROPER(TRIM(H5)))) -> Online | T5: =IF(UPPER(TRIM(L5))="CC","Credit Card",PROPER(TRIM(L5))) -> Cash | U5: =IF(PROPER(TRIM(M5))="Complete","Completed",IF(PROPER(TRIM(M5))="Canceled","Cancelled",PROPER(TRIM(M5)))) -> Cancelled | V5: =IFERROR(VALUE(TRIM(I5)),"") -> 12 | W5: =IFERROR(VALUE(SUBSTITUTE(TRIM(J5),"$","")),"") -> 411.55 | X5: =IFERROR(IF(ISNUMBER(tblOrders[[#This Row],[OrderDate]]),tblOrders[[#This Row],[OrderDate]],IFERROR(DATEVALUE(tblOrders[[#This Row],[OrderDate]]),DATE(IF(LEN(TRIM(tblOrders[[#This Row],[OrderDate]]))=8,2000+VALUE(RIGHT(TRIM(tblOrders[[#This Row],[OrderDate]]),2)),VALUE(RIGHT(TRIM(tblOrders[[#This Row],[OrderDate]]),4))),VALUE(MID(TRIM(tblOrders[[#This Row],[OrderDate]]),4,2)),VALUE(LEFT(TRIM(tblOrders[[#This Row],[OrderDate]]),2))))),"CHECK MANUALLY") -> 45379 | Y5: =IF(K5="",0,K5) -> 0 | Z5: =TRIM(CLEAN(tblOrders[[#This Row],[Notes]])) | AA5: =IF(OR(V5="",W5=""),"Review",IF(V5*W5>=1000,"High Value","Standard")) -> High Value | AB5: =IF(OR(tblOrders[[#This Row],[Quantity_Clean]]="",tblOrders[[#This Row],[UnitPrice_Clean]]=""),0,tblOrders[[#This Row],[Quantity_Clean]]*tblOrders[[#This Row],[UnitPrice_Clean]]) -> 4938.6 | AC5: =UPPER(TRIM(tblOrders[[#This Row],[OrderID]])) -> ORD-1212 | AD5: =VALUE(RIGHT(tblOrders[[#This Row],[OrderID]],4)) -> 1212 | AE5: =TEXT(tblOrders[[#This Row],[OrderDate_Clean]],"mmm-yyyy") -> Mar-2024 | AF5: =EOMONTH(tblOrders[[#This Row],[OrderDate_Clean]],0) -> 45382 | AG5: David | AH5: =IF(tblOrders[[#This Row],[Discount]]="",0,IF(ISNUMBER(tblOrders[[#This Row],[Discount]]),tblOrders[[#This Row],[Discount]],VALUE(SUBSTITUTE(TRIM(tblOrders[[#This Row],[Discount]]),"%",""))/100)) -> 0
A6: ORD-1018 | B6: 25/02/2024 | C6: UMAR FAROOQ | D6: south | E6: Karachi | F6: Furniture | G6: Office Chair | H6: ONLINE | I6: 12 | J6: 392.28 | K6: 5% | L6: CC | M6: COMPLETED | O6: Gift wrap requested | P6: =PROPER(TRIM(C6)) -> Umar Farooq | Q6: =IF(OR(PROPER(TRIM(tblOrders[[#This Row],[Region]]))="Nort",PROPER(TRIM(tblOrders[[#This Row],[Region]]))="Northh"),"North",PROPER(TRIM(tblOrders[[#This Row],[Region]]))) -> South | R6: =IF(PROPER(TRIM(F6))="Cloth Ing","Clothing",IF(PROPER(TRIM(F6))="Electronic","Electronics",IF(PROPER(TRIM(F6))="Grocery","Groceries",SUBSTITUTE(PROPER(TRIM(F6)),"Stationary","Stationery")))) -> Furniture | S6: =IF(LOWER(TRIM(H6))="online","Online",IF(OR(LOWER(TRIM(H6))="in-store",LOWER(TRIM(H6))="in store",LOWER(TRIM(H6))="instore"),"In-Store",PROPER(TRIM(H6)))) -> Online | T6: =IF(UPPER(TRIM(L6))="CC","Credit Card",PROPER(TRIM(L6))) -> Credit Card | U6: =IF(PROPER(TRIM(M6))="Complete","Completed",IF(PROPER(TRIM(M6))="Canceled","Cancelled",PROPER(TRIM(M6)))) -> Completed | V6: =IFERROR(VALUE(TRIM(I6)),"") -> 12 | W6: =IFERROR(VALUE(SUBSTITUTE(TRIM(J6),"$","")),"") -> 392.28 | X6: =IFERROR(IF(ISNUMBER(tblOrders[[#This Row],[OrderDate]]),tblOrders[[#This Row],[OrderDate]],IFERROR(DATEVALUE(tblOrders[[#This Row],[OrderDate]]),DATE(IF(LEN(TRIM(tblOrders[[#This Row],[OrderDate]]))=8,2000+VALUE(RIGHT(TRIM(tblOrders[[#This Row],[OrderDate]]),2)),VALUE(RIGHT(TRIM(tblOrders[[#This Row],[OrderDate]]),4))),VALUE(MID(TRIM(tblOrders[[#This Row],[OrderDate]]),4,2)),VALUE(LEFT(TRIM(tblOrders[[#This Row],[OrderDate]]),2))))),"CHECK MANUALLY") -> 45347 | Y6: =IF(K6="",0,K6) -> 5% | Z6: =TRIM(CLEAN(tblOrders[[#This Row],[Notes]])) -> Gift wrap requested | AA6: =IF(OR(V6="",W6=""),"Review",IF(V6*W6>=1000,"High Value","Standard")) -> High Value | AB6: =IF(OR(tblOrders[[#This Row],[Quantity_Clean]]="",tblOrders[[#This Row],[UnitPrice_Clean]]=""),0,tblOrders[[#This Row],[Quantity_Clean]]*tblOrders[[#This Row],[UnitPrice_Clean]]) -> 4707.36 | AC6: =UPPER(TRIM(tblOrders[[#This Row],[OrderID]])) -> ORD-1018 | AD6: =VALUE(RIGHT(tblOrders[[#This Row],[OrderID]],4)) -> 1018 | AE6: =TEXT(tblOrders[[#This Row],[OrderDate_Clean]],"mmm-yyyy") -> Feb-2024 | AF6: =EOMONTH(tblOrders[[#This Row],[OrderDate_Clean]],0) -> 45351 | AG6: UMAR | AH6: =IF(tblOrders[[#This Row],[Discount]]="",0,IF(ISNUMBER(tblOrders[[#This Row],[Discount]]),tblOrders[[#This Row],[Discount]],VALUE(SUBSTITUTE(TRIM(tblOrders[[#This Row],[Discount]]),"%",""))/100)) -> 0.05
A7: ORD-1095 | B7: 06-May-24 | C7: Kevin Garcia | D7: East | E7: Sialkot | F7: Furniture | G7: Sofa Set | H7: in-store | I7: 9 | J7: 387.13 | K7: 10% | L7: cash | M7: CANCELLED | N7: B. Fernandes | O7: Bulk order - business account | P7: =PROPER(TRIM(C7)) -> Kevin Garcia | Q7: =IF(OR(PROPER(TRIM(tblOrders[[#This Row],[Region]]))="Nort",PROPER(TRIM(tblOrders[[#This Row],[Region]]))="Northh"),"North",PROPER(TRIM(tblOrders[[#This Row],[Region]]))) -> East | R7: =IF(PROPER(TRIM(F7))="Cloth Ing","Clothing",IF(PROPER(TRIM(F7))="Electronic","Electronics",IF(PROPER(TRIM(F7))="Grocery","Groceries",SUBSTITUTE(PROPER(TRIM(F7)),"Stationary","Stationery")))) -> Furniture | S7: =IF(LOWER(TRIM(H7))="online","Online",IF(OR(LOWER(TRIM(H7))="in-store",LOWER(TRIM(H7))="in store",LOWER(TRIM(H7))="instore"),"In-Store",PROPER(TRIM(H7)))) -> In-Store | T7: =IF(UPPER(TRIM(L7))="CC","Credit Card",PROPER(TRIM(L7))) -> Cash | U7: =IF(PROPER(TRIM(M7))="Complete","Completed",IF(PROPER(TRIM(M7))="Canceled","Cancelled",PROPER(TRIM(M7)))) -> Cancelled | V7: =IFERROR(VALUE(TRIM(I7)),"") -> 9 | W7: =IFERROR(VALUE(SUBSTITUTE(TRIM(J7),"$","")),"") -> 387.13 | X7: =IFERROR(IF(ISNUMBER(tblOrders[[#This Row],[OrderDate]]),tblOrders[[#This Row],[OrderDate]],IFERROR(DATEVALUE(tblOrders[[#This Row],[OrderDate]]),DATE(IF(LEN(TRIM(tblOrders[[#This Row],[OrderDate]]))=8,2000+VALUE(RIGHT(TRIM(tblOrders[[#This Row],[OrderDate]]),2)),VALUE(RIGHT(TRIM(tblOrders[[#This Row],[OrderDate]]),4))),VALUE(MID(TRIM(tblOrders[[#This Row],[OrderDate]]),4,2)),VALUE(LEFT(TRIM(tblOrders[[#This Row],[OrderDate]]),2))))),"CHECK MANUALLY") -> 45418 | Y7: =IF(K7="",0,K7) -> 10% | Z7: =TRIM(CLEAN(tblOrders[[#This Row],[Notes]])) -> Bulk order - business account | AA7: =IF(OR(V7="",W7=""),"Review",IF(V7*W7>=1000,"High Value","Standard")) -> High Value | AB7: =IF(OR(tblOrders[[#This Row],[Quantity_Clean]]="",tblOrders[[#This Row],[UnitPrice_Clean]]=""),0,tblOrders[[#This Row],[Quantity_Clean]]*tblOrders[[#This Row],[UnitPrice_Clean]]) -> 3484.17 | AC7: =UPPER(TRIM(tblOrders[[#This Row],[OrderID]])) -> ORD-1095 | AD7: =VALUE(RIGHT(tblOrders[[#This Row],[OrderID]],4)) -> 1095 | AE7: =TEXT(tblOrders[[#This Row],[OrderDate_Clean]],"mmm-yyyy") -> May-2024 | AF7: =EOMONTH(tblOrders[[#This Row],[OrderDate_Clean]],0) -> 45443 | AG7: Kevin | AH7: =IF(tblOrders[[#This Row],[Discount]]="",0,IF(ISNUMBER(tblOrders[[#This Row],[Discount]]),tblOrders[[#This Row],[Discount]],VALUE(SUBSTITUTE(TRIM(tblOrders[[#This Row],[Discount]]),"%",""))/100)) -> 0.1
A8: ORD-1227 | B8: 2024-07-22 | C8: Liam Anderson | D8: south | E8: Hyderabad | F8: Furniture | G8: Filing Cabinet | H8: ONLINE | I8: 11 | J8: 361.68 | L8: Cash | M8: pending | N8: A. Malik | O8: Follow up needed | P8: =PROPER(TRIM(C8)) -> Liam Anderson | Q8: =IF(OR(PROPER(TRIM(tblOrders[[#This Row],[Region]]))="Nort",PROPER(TRIM(tblOrders[[#This Row],[Region]]))="Northh"),"North",PROPER(TRIM(tblOrders[[#This Row],[Region]]))) -> South | R8: =IF(PROPER(TRIM(F8))="Cloth Ing","Clothing",IF(PROPER(TRIM(F8))="Electronic","Electronics",IF(PROPER(TRIM(F8))="Grocery","Groceries",SUBSTITUTE(PROPER(TRIM(F8)),"Stationary","Stationery")))) -> Furniture | S8: =IF(LOWER(TRIM(H8))="online","Online",IF(OR(LOWER(TRIM(H8))="in-store",LOWER(TRIM(H8))="in store",LOWER(TRIM(H8))="instore"),"In-Store",PROPER(TRIM(H8)))) -> Online | T8: =IF(UPPER(TRIM(L8))="CC","Credit Card",PROPER(TRIM(L8))) -> Cash | U8: =IF(PROPER(TRIM(M8))="Complete","Completed",IF(PROPER(TRIM(M8))="Canceled","Cancelled",PROPER(TRIM(M8)))) -> Pending | V8: =IFERROR(VALUE(TRIM(I8)),"") -> 11 | W8: =IFERROR(VALUE(SUBSTITUTE(TRIM(J8),"$","")),"") -> 361.68 | X8: =IFERROR(IF(ISNUMBER(tblOrders[[#This Row],[OrderDate]]),tblOrders[[#This Row],[OrderDate]],IFERROR(DATEVALUE(tblOrders[[#This Row],[OrderDate]]),DATE(IF(LEN(TRIM(tblOrders[[#This Row],[OrderDate]]))=8,2000+VALUE(RIGHT(TRIM(tblOrders[[#This Row],[OrderDate]]),2)),VALUE(RIGHT(TRIM(tblOrders[[#This Row],[OrderDate]]),4))),VALUE(MID(TRIM(tblOrders[[#This Row],[OrderDate]]),4,2)),VALUE(LEFT(TRIM(tblOrders[[#This Row],[OrderDate]]),2))))),"CHECK MANUALLY") -> 45495 | Y8: =IF(K8="",0,K8) -> 0 | Z8: =TRIM(CLEAN(tblOrders[[#This Row],[Notes]])) -> Follow up needed | AA8: =IF(OR(V8="",W8=""),"Review",IF(V8*W8>=1000,"High Value","Standard")) -> High Value | AB8: =IF(OR(tblOrders[[#This Row],[Quantity_Clean]]="",tblOrders[[#This Row],[UnitPrice_Clean]]=""),0,tblOrders[[#This Row],[Quantity_Clean]]*tblOrders[[#This Row],[UnitPrice_Clean]]) -> 3978.48 | AC8: =UPPER(TRIM(tblOrders[[#This Row],[OrderID]])) -> ORD-1227 | AD8: =VALUE(RIGHT(tblOrders[[#This Row],[OrderID]],4)) -> 1227 | AE8: =TEXT(tblOrders[[#This Row],[OrderDate_Clean]],"mmm-yyyy") -> Jul-2024 | AF8: =EOMONTH(tblOrders[[#This Row],[OrderDate_Clean]],0) -> 45504 | AG8: Liam | AH8: =IF(tblOrders[[#This Row],[Discount]]="",0,IF(ISNUMBER(tblOrders[[#This Row],[Discount]]),tblOrders[[#This Row],[Discount]],VALUE(SUBSTITUTE(TRIM(tblOrders[[#This Row],[Discount]]),"%",""))/100)) -> 0
A9: ORD-1147 | B9: 04-Oct-24 | C9: daniel smith | D9: SOUTH | E9: Hyderabad | F9: Furniture | G9: Bookshelf | H9: instore | I9: 4 | J9: 275.55 | L9: debit card | M9: Completed | N9: B. Fernandes | O9: Gift wrap requested | P9: =PROPER(TRIM(C9)) -> Daniel Smith | Q9: =IF(OR(PROPER(TRIM(tblOrders[[#This Row],[Region]]))="Nort",PROPER(TRIM(tblOrders[[#This Row],[Region]]))="Northh"),"North",PROPER(TRIM(tblOrders[[#This Row],[Region]]))) -> South | R9: =IF(PROPER(TRIM(F9))="Cloth Ing","Clothing",IF(PROPER(TRIM(F9))="Electronic","Electronics",IF(PROPER(TRIM(F9))="Grocery","Groceries",SUBSTITUTE(PROPER(TRIM(F9)),"Stationary","Stationery")))) -> Furniture | S9: =IF(LOWER(TRIM(H9))="online","Online",IF(OR(LOWER(TRIM(H9))="in-store",LOWER(TRIM(H9))="in store",LOWER(TRIM(H9))="instore"),"In-Store",PROPER(TRIM(H9)))) -> In-Store | T9: =IF(UPPER(TRIM(L9))="CC","Credit Card",PROPER(TRIM(L9))) -> Debit Card | U9: =IF(PROPER(TRIM(M9))="Complete","Completed",IF(PROPER(TRIM(M9))="Canceled","Cancelled",PROPER(TRIM(M9)))) -> Completed | V9: =IFERROR(VALUE(TRIM(I9)),"") -> 4 | W9: =IFERROR(VALUE(SUBSTITUTE(TRIM(J9),"$","")),"") -> 275.55 | X9: =IFERROR(IF(ISNUMBER(tblOrders[[#This Row],[OrderDate]]),tblOrders[[#This Row],[OrderDate]],IFERROR(DATEVALUE(tblOrders[[#This Row],[OrderDate]]),DATE(IF(LEN(TRIM(tblOrders[[#This Row],[OrderDate]]))=8,2000+VALUE(RIGHT(TRIM(tblOrders[[#This Row],[OrderDate]]),2)),VALUE(RIGHT(TRIM(tblOrders[[#This Row],[OrderDate]]),4))),VALUE(MID(TRIM(tblOrders[[#This Row],[OrderDate]]),4,2)),VALUE(LEFT(TRIM(tblOrders[[#This Row],[OrderDate]]),2))))),"CHECK MANUALLY") -> 45569 | Y9: =IF(K9="",0,K9) -> 0 | Z9: =TRIM(CLEAN(tblOrders[[#This Row],[Notes]])) -> Gift wrap requested | AA9: =IF(OR(V9="",W9=""),"Review",IF(V9*W9>=1000,"High Value","Standard")) -> High Value | AB9: =IF(OR(tblOrders[[#This Row],[Quantity_Clean]]="",tblOrders[[#This Row],[UnitPrice_Clean]]=""),0,tblOrders[[#This Row],[Quantity_Clean]]*tblOrders[[#This Row],[UnitPrice_Clean]]) -> 1102.2 | AC9: =UPPER(TRIM(tblOrders[[#This Row],[OrderID]])) -> ORD-1147 | AD9: =VALUE(RIGHT(tblOrders[[#This Row],[OrderID]],4)) -> 1147 | AE9: =TEXT(tblOrders[[#This Row],[OrderDate_Clean]],"mmm-yyyy") -> Oct-2024 | AF9: =EOMONTH(tblOrders[[#This Row],[OrderDate_Clean]],0) -> 45596 | AG9: daniel | AH9: =IF(tblOrders[[#This Row],[Discount]]="",0,IF(ISNUMBER(tblOrders[[#This Row],[Discount]]),tblOrders[[#This Row],[Discount]],VALUE(SUBSTITUTE(TRIM(tblOrders[[#This Row],[Discount]]),"%",""))/100)) -> 0
A10: ORD-1045 | B10: September 14, 2024 | C10: UMAR FAROOQ | D10: WEST | E10: Quetta | F10: Furniture | G10: Study Desk | H10: In Store | I10: 1 | J10: 239.12 | K10: 0.05 | L10: Debit card | M10: Completed | N10: B. Fernandes | P10: =PROPER(TRIM(C10)) -> Umar Farooq | Q10: =IF(OR(PROPER(TRIM(tblOrders[[#This Row],[Region]]))="Nort",PROPER(TRIM(tblOrders[[#This Row],[Region]]))="Northh"),"North",PROPER(TRIM(tblOrders[[#This Row],[Region]]))) -> West | R10: =IF(PROPER(TRIM(F10))="Cloth Ing","Clothing",IF(PROPER(TRIM(F10))="Electronic","Electronics",IF(PROPER(TRIM(F10))="Grocery","Groceries",SUBSTITUTE(PROPER(TRIM(F10)),"Stationary","Stationery")))) -> Furniture | S10: =IF(LOWER(TRIM(H10))="online","Online",IF(OR(LOWER(TRIM(H10))="in-store",LOWER(TRIM(H10))="in store",LOWER(TRIM(H10))="instore"),"In-Store",PROPER(TRIM(H10)))) -> In-Store | T10: =IF(UPPER(TRIM(L10))="CC","Credit Card",PROPER(TRIM(L10))) -> Debit Card | U10: =IF(PROPER(TRIM(M10))="Complete","Completed",IF(PROPER(TRIM(M10))="Canceled","Cancelled",PROPER(TRIM(M10)))) -> Completed | V10: =IFERROR(VALUE(TRIM(I10)),"") -> 1 | W10: =IFERROR(VALUE(SUBSTITUTE(TRIM(J10),"$","")),"") -> 239.12 | X10: =IFERROR(IF(ISNUMBER(tblOrders[[#This Row],[OrderDate]]),tblOrders[[#This Row],[OrderDate]],IFERROR(DATEVALUE(tblOrders[[#This Row],[OrderDate]]),DATE(IF(LEN(TRIM(tblOrders[[#This Row],[OrderDate]]))=8,2000+VALUE(RIGHT(TRIM(tblOrders[[#This Row],[OrderDate]]),2)),VALUE(RIGHT(TRIM(tblOrders[[#This Row],[OrderDate]]),4))),VALUE(MID(TRIM(tblOrders[[#This Row],[OrderDate]]),4,2)),VALUE(LEFT(TRIM(tblOrders[[#This Row],[OrderDate]]),2))))),"CHECK MANUALLY") -> 45549 | Y10: =IF(K10="",0,K10) -> 0.05 | Z10: =TRIM(CLEAN(tblOrders[[#This Row],[Notes]])) | AA10: =IF(OR(V10="",W10=""),"Review",IF(V10*W10>=1000,"High Value","Standard")) -> Standard | AB10: =IF(OR(tblOrders[[#This Row],[Quantity_Clean]]="",tblOrders[[#This Row],[UnitPrice_Clean]]=""),0,tblOrders[[#This Row],[Quantity_Clean]]*tblOrders[[#This Row],[UnitPrice_Clean]]) -> 239.12 | AC10: =UPPER(TRIM(tblOrders[[#This Row],[OrderID]])) -> ORD-1045 | AD10: =VALUE(RIGHT(tblOrders[[#This Row],[OrderID]],4)) -> 1045 | AE10: =TEXT(tblOrders[[#This Row],[OrderDate_Clean]],"mmm-yyyy") -> Sep-2024 | AF10: =EOMONTH(tblOrders[[#This Row],[OrderDate_Clean]],0) -> 45565 | AG10: UMAR | AH10: =IF(tblOrders[[#This Row],[Discount]]="",0,IF(ISNUMBER(tblOrders[[#This Row],[Discount]]),tblOrders[[#This Row],[Discount]],VALUE(SUBSTITUTE(TRIM(tblOrders[[#This Row],[Discount]]),"%",""))/100)) -> 0.05
